#starting xUnitTest
#error xUnitTest instance of 'std::exception'